2020-04-19 13:00:24,087 root - ERROR - Error at division
Traceback (most recent call last):
  File "testtrack.py", line 379, in mainquery
    adddata(country, changes[1], changes[0])
  File "testtrack.py", line 336, in adddata
    raise Exception(f'Attempted to add {number} at {testdatestring} for {country} but cell not empty')
Exception: Attempted to add 460437 at 18/4/2020 for UK but cell not empty
2020-04-19 13:00:28,923 root - ERROR - Error at division
Traceback (most recent call last):
  File "C:\Users\Tom\AppData\Local\Programs\Python\Python38-32\lib\urllib\request.py", line 1319, in do_open
    h.request(req.get_method(), req.selector, req.data, headers,
  File "C:\Users\Tom\AppData\Local\Programs\Python\Python38-32\lib\http\client.py", line 1230, in request
    self._send_request(method, url, body, headers, encode_chunked)
  File "C:\Users\Tom\AppData\Local\Programs\Python\Python38-32\lib\http\client.py", line 1276, in _send_request
    self.endheaders(body, encode_chunked=encode_chunked)
  File "C:\Users\Tom\AppData\Local\Programs\Python\Python38-32\lib\http\client.py", line 1225, in endheaders
    self._send_output(message_body, encode_chunked=encode_chunked)
  File "C:\Users\Tom\AppData\Local\Programs\Python\Python38-32\lib\http\client.py", line 1004, in _send_output
    self.send(msg)
  File "C:\Users\Tom\AppData\Local\Programs\Python\Python38-32\lib\http\client.py", line 944, in send
    self.connect()
  File "C:\Users\Tom\AppData\Local\Programs\Python\Python38-32\lib\http\client.py", line 1392, in connect
    super().connect()
  File "C:\Users\Tom\AppData\Local\Programs\Python\Python38-32\lib\http\client.py", line 915, in connect
    self.sock = self._create_connection(
  File "C:\Users\Tom\AppData\Local\Programs\Python\Python38-32\lib\socket.py", line 787, in create_connection
    for res in getaddrinfo(host, port, 0, SOCK_STREAM):
  File "C:\Users\Tom\AppData\Local\Programs\Python\Python38-32\lib\socket.py", line 918, in getaddrinfo
    for res in _socket.getaddrinfo(host, port, family, type, proto, flags):
socket.gaierror: [Errno 11002] getaddrinfo failed

During handling of the above exception, another exception occurred:

Traceback (most recent call last):
  File "testtrack.py", line 354, in mainquery
    changes = TrackChanges(country)
  File "testtrack.py", line 62, in TrackChanges
    page = urllib.request.urlopen(pages["SK"])
  File "C:\Users\Tom\AppData\Local\Programs\Python\Python38-32\lib\urllib\request.py", line 222, in urlopen
    return opener.open(url, data, timeout)
  File "C:\Users\Tom\AppData\Local\Programs\Python\Python38-32\lib\urllib\request.py", line 525, in open
    response = self._open(req, data)
  File "C:\Users\Tom\AppData\Local\Programs\Python\Python38-32\lib\urllib\request.py", line 542, in _open
    result = self._call_chain(self.handle_open, protocol, protocol +
  File "C:\Users\Tom\AppData\Local\Programs\Python\Python38-32\lib\urllib\request.py", line 502, in _call_chain
    result = func(*args)
  File "C:\Users\Tom\AppData\Local\Programs\Python\Python38-32\lib\urllib\request.py", line 1362, in https_open
    return self.do_open(http.client.HTTPSConnection, req,
  File "C:\Users\Tom\AppData\Local\Programs\Python\Python38-32\lib\urllib\request.py", line 1322, in do_open
    raise URLError(err)
urllib.error.URLError: <urlopen error [Errno 11002] getaddrinfo failed>
2020-04-19 13:00:35,286 root - ERROR - Error at division
Traceback (most recent call last):
  File "testtrack.py", line 379, in mainquery
    adddata(country, changes[1], changes[0])
  File "testtrack.py", line 336, in adddata
    raise Exception(f'Attempted to add {number} at {testdatestring} for {country} but cell not empty')
Exception: Attempted to add 528057 at 18/4/2020 for CAN but cell not empty
2020-04-19 13:00:37,236 tabula.io - WARNING - 'pages' argument isn't specified.Will extract only from page 1 by default.
2020-04-19 13:00:45,417 tabula.io - WARNING - Got stderr: Apr 19, 2020 1:00:40 PM org.apache.pdfbox.pdmodel.font.PDCIDFontType2 <init>
INFO: OpenType Layout tables used in font CIDFont+F1 are not implemented in PDFBox and will be ignored
Apr 19, 2020 1:00:40 PM org.apache.pdfbox.pdmodel.font.PDCIDFontType2 <init>
INFO: OpenType Layout tables used in font CIDFont+F2 are not implemented in PDFBox and will be ignored
Apr 19, 2020 1:00:40 PM org.apache.pdfbox.pdmodel.font.PDCIDFontType2 <init>
INFO: OpenType Layout tables used in font CIDFont+F3 are not implemented in PDFBox and will be ignored
Apr 19, 2020 1:00:41 PM org.apache.pdfbox.pdmodel.font.PDCIDFontType2 <init>
INFO: OpenType Layout tables used in font CIDFont+F1 are not implemented in PDFBox and will be ignored
Apr 19, 2020 1:00:41 PM org.apache.pdfbox.pdmodel.font.PDCIDFontType2 <init>
INFO: OpenType Layout tables used in font CIDFont+F2 are not implemented in PDFBox and will be ignored
Apr 19, 2020 1:00:42 PM org.apache.pdfbox.pdmodel.font.PDCIDFontType2 <init>
INFO: OpenType Layout tables used in font CIDFont+F3 are not implemented in PDFBox and will be ignored
Apr 19, 2020 1:00:44 PM org.apache.pdfbox.pdmodel.font.PDCIDFontType2 <init>
INFO: OpenType Layout tables used in font CIDFont+F1 are not implemented in PDFBox and will be ignored
Apr 19, 2020 1:00:44 PM org.apache.pdfbox.pdmodel.font.PDCIDFontType2 <init>
INFO: OpenType Layout tables used in font CIDFont+F2 are not implemented in PDFBox and will be ignored
Apr 19, 2020 1:00:44 PM org.apache.pdfbox.pdmodel.font.PDCIDFontType2 <init>
INFO: OpenType Layout tables used in font CIDFont+F3 are not implemented in PDFBox and will be ignored

2020-04-19 13:00:45,511 root - ERROR - Error at division
Traceback (most recent call last):
  File "testtrack.py", line 379, in mainquery
    adddata(country, changes[1], changes[0])
  File "testtrack.py", line 336, in adddata
    raise Exception(f'Attempted to add {number} at {testdatestring} for {country} but cell not empty')
Exception: Attempted to add 1305833 at 18/4/2020 for IT but cell not empty
2020-04-19 13:00:47,718 root - ERROR - Error at division
Traceback (most recent call last):
  File "testtrack.py", line 379, in mainquery
    adddata(country, changes[1], changes[0])
  File "testtrack.py", line 336, in adddata
    raise Exception(f'Attempted to add {number} at {testdatestring} for {country} but cell not empty')
Exception: Attempted to add 179243 at 18/4/2020 for AUST but cell not empty
2020-04-19 13:00:54,016 root - ERROR - Error at division
Traceback (most recent call last):
  File "testtrack.py", line 354, in mainquery
    changes = TrackChanges(country)
  File "testtrack.py", line 137, in TrackChanges
    testdate = soup.find("p", class_="m-boxInfo__date").find("time")['datetime']
AttributeError: 'NoneType' object has no attribute 'find'
2020-04-19 13:00:57,115 root - ERROR - Error at division
Traceback (most recent call last):
  File "testtrack.py", line 354, in mainquery
    changes = TrackChanges(country)
  File "testtrack.py", line 163, in TrackChanges
    testnumber = re.findall('[0-9]+', text)[3]
IndexError: list index out of range
2020-04-19 13:00:58,441 root - ERROR - Error at division
Traceback (most recent call last):
  File "testtrack.py", line 354, in mainquery
    changes = TrackChanges(country)
  File "testtrack.py", line 170, in TrackChanges
    testnumber = re.findall('[0-9]+', text)
  File "C:\Users\Tom\AppData\Local\Programs\Python\Python38-32\lib\re.py", line 239, in findall
    return _compile(pattern, flags).findall(string)
TypeError: expected string or bytes-like object
2020-04-19 13:00:59,161 root - ERROR - Error at division
Traceback (most recent call last):
  File "testtrack.py", line 379, in mainquery
    adddata(country, changes[1], changes[0])
  File "testtrack.py", line 336, in adddata
    raise Exception(f'Attempted to add {number} at {testdatestring} for {country} but cell not empty')
Exception: Attempted to add 148508 at 16/4/2020 for NED but cell not empty
2020-04-19 13:01:04,642 root - ERROR - Error at division
Traceback (most recent call last):
  File "testtrack.py", line 379, in mainquery
    adddata(country, changes[1], changes[0])
  File "testtrack.py", line 327, in adddata
    raise Exception(
Exception: Tests cannot decrease for RUS, largest value is 1831892.0 and attempting to add 1949
2020-04-19 13:01:15,427 root - ERROR - Error at division
Traceback (most recent call last):
  File "testtrack.py", line 379, in mainquery
    adddata(country, changes[1], changes[0])
  File "testtrack.py", line 336, in adddata
    raise Exception(f'Attempted to add {number} at {testdatestring} for {country} but cell not empty')
Exception: Attempted to add 36028 at 18/4/2020 for SRB but cell not empty
2020-04-19 13:01:17,696 root - ERROR - Error at division
Traceback (most recent call last):
  File "testtrack.py", line 354, in mainquery
    changes = TrackChanges(country)
  File "testtrack.py", line 227, in TrackChanges
    test = re.findall('[0-9. ]+', text)
  File "C:\Users\Tom\AppData\Local\Programs\Python\Python38-32\lib\re.py", line 239, in findall
    return _compile(pattern, flags).findall(string)
TypeError: expected string or bytes-like object
2020-04-19 13:01:17,701 root - ERROR - Error at division
Traceback (most recent call last):
  File "testtrack.py", line 354, in mainquery
    changes = TrackChanges(country)
  File "testtrack.py", line 307, in TrackChanges
    testnumber, testdate = clearstring(testnumber, testdate)
UnboundLocalError: local variable 'testnumber' referenced before assignment
2020-04-19 13:01:21,474 root - ERROR - Error at division
Traceback (most recent call last):
  File "testtrack.py", line 354, in mainquery
    changes = TrackChanges(country)
  File "testtrack.py", line 307, in TrackChanges
    testnumber, testdate = clearstring(testnumber, testdate)
UnboundLocalError: local variable 'testnumber' referenced before assignment
2020-04-19 13:01:21,475 root - ERROR - Error at division
Traceback (most recent call last):
  File "testtrack.py", line 354, in mainquery
    changes = TrackChanges(country)
  File "testtrack.py", line 307, in TrackChanges
    testnumber, testdate = clearstring(testnumber, testdate)
UnboundLocalError: local variable 'testnumber' referenced before assignment
2020-04-19 13:01:21,475 root - ERROR - Error at division
Traceback (most recent call last):
  File "testtrack.py", line 354, in mainquery
    changes = TrackChanges(country)
  File "testtrack.py", line 307, in TrackChanges
    testnumber, testdate = clearstring(testnumber, testdate)
UnboundLocalError: local variable 'testnumber' referenced before assignment
2020-04-19 13:01:21,475 root - ERROR - Error at division
Traceback (most recent call last):
  File "testtrack.py", line 354, in mainquery
    changes = TrackChanges(country)
  File "testtrack.py", line 307, in TrackChanges
    testnumber, testdate = clearstring(testnumber, testdate)
UnboundLocalError: local variable 'testnumber' referenced before assignment
2020-04-19 13:01:33,593 root - ERROR - Error at division
Traceback (most recent call last):
  File "testtrack.py", line 379, in mainquery
    adddata(country, changes[1], changes[0])
  File "testtrack.py", line 336, in adddata
    raise Exception(f'Attempted to add {number} at {testdatestring} for {country} but cell not empty')
Exception: Attempted to add 52500 at 17/4/2020 for FIN but cell not empty
2020-04-19 13:01:50,983 root - ERROR - Error at division
Traceback (most recent call last):
  File "testtrack.py", line 354, in mainquery
    changes = TrackChanges(country)
  File "testtrack.py", line 288, in TrackChanges
    words = re.findall('(?<=of)(((\d+)|(,)|(\s+))+)(?=samples)', words)[0][0]
IndexError: list index out of range
2020-04-19 13:02:08,870 root - ERROR - Error at division
Traceback (most recent call last):
  File "testtrack.py", line 354, in mainquery
    changes = TrackChanges(country)
  File "testtrack.py", line 302, in TrackChanges
    testdate = soup.find("small", class_="text-muted1").find("strong").get_text()
AttributeError: 'NoneType' object has no attribute 'find'
